Workbook

Sheet THỰC ĐƠN VINALPHA
B1: CÔNG TY: HSS
B2: THỰC ĐƠN SUẤT ĂN CA CÔNG NHÂN
B3: Dự án:
B4: (TỪ 17/08/2026 đến 23/08/2026)
B5: Thứ | C5: SÁNG | F5: TRƯA | I5: TỐI | L5: ĐÊM
C6: Món | D6: Trọng lượng thành phẩm | F6: Món | G6: Trọng lượng thành phẩm | I6: Món | J6: Trọng lượng thành phẩm | L6: Món | M6: Trọng lượng thành phẩm
B7: Thứ 2 | C7: Bánh bao | D7: 160g-180g | F7: Thịt xào hành tây | G7: Thịt 50g + hành tây 10g | I7: Gà kho nghệ | J7: 60g-80g | L7: Bún riêu cua cá
C8: Trứng luộc | D8: 1 quả | F8: Tôm rang lá chanh | G8: 30g-35g | I8: Thăn cá chiên xù | J8: 50g-60g | L8: Bún tươi | M8: 230g-250g
C9: Sữa fami | D9: 180ml | F9: Trứng cút rim tiêu | G9: 4 quả | I9: Chuối om thịt | J9: 60g-70g | L9: Cá chiên | M9: 40g-45g
F10: Bắp cải luộc | G10: 75g-80g | I10: Rau muống luộc | J10: 75g-80g | L10: Sữa izzi | M10: 180ml
F11: Cơm trắng | G11: 200-250gr | I11: Cơm trắng | J11: 200-250gr
F12: Canh rau ngót | G12: 300-350gr | I12: Nước luộc dầm chua | J12: 300-350gr
F13: Ổi | G13: 80g | I13: Thanh long | J13: 80g
B15: Thứ 3 | C15: Cháo ngao | D15: 200-230g | F15: Bò nấu sốt vang | G15: Bò 40g-45g+ khoai 20g | I15: Cá sốt cà chua | J15: 80g-100g | L15: Xôi gà đỗ xanh
C16: Trứng vịt lộn | D16: 1 quả | F16: Ức gà xào hành nấm | G16: Ức gà 50g+ hành nấm 15g | I16: Tim xào dưa | J16: Tim 40g + dưa 20g | L16: Gà xé | M16: 40g-45g
C17: Quẩy | D17: 1 cái | F17: Đậu sốt cà chua | G17: 40g-50g | I17: Lạc chao | J17: 20g-30g | L17: Sữa fami | M17: 180ml
F18: Đỗ cove luộc | G18: 75g-80g | I18: Bí xanh luộc | J18: 75g-80g
F19: Cơm trắng | G19: 200-250gr | I19: Cơm trắng | J19: 200-250gr
F20: Canh rau dền | G20: 300-350gr | I20: Canh cải xanh | J20: 300-350gr
F21: Chuối | G21: 1 quả | I21: Dưa hấu | J21: 80g
B23: Thứ 4 | C23: Bún chấm | D23: 200g-230g | F23: Gà chiên mắm | G23: 60g-80g | I23: Sườn chua ngọt | J23: 60g-80g | L23: Cháo Sườn ngô
C24: Thịt nướng | D24: 25g-30g | F24: Tôm rim me | G24: 30g-35g | I24: Trứng đúc thịt | J24: 50g-60g | L24: Sườn | M24: 60g
F25: Mướp đắng xào trứng | G25: 60g | I25: Đậu om cà | J25: 60g | L25: Ngô ngọt | M25: 20g-25g
F26: Rau muống luộc | G26: 75g-80g | I26: Củ cải luộc | J26: 75g-80g | L26: Sữa tươi ba vì | M26: 110ml
F27: Cơm trắng | G27: 200-250gr | I27: Cơm trắng | J27: 200-250gr
F28: Nước luộc dầm chua | G28: 300-350gr | I28: Canh rau ngót | J28: 300-350gr
F29: Cam | G29: 80g | I29: Ổi | J29: 80g
B31: Thứ 5 | C31: Xôi giò rim | D31: 180g-200g | F31: Vịt om sấu khoai môn | G31: 60g-80g | I31: Bò kho củ cải | J31: Bò 40g-45g+ củ cải 20g | L31: Bánh cuốn chả mực + thịt nướng
C32: Sữa fami | D32: 180ml | F32: Thịt xào su su | G32: Thịt 50g+ su su 20g | I32: Chả cá sốt thì là | J32: 50g-60g | L32: Bánh cuốn | M32: 230g-250g
F33: Lạc chao | G33: 20g-25g | I33: Thịt băm om chuối | J33: 60g-70g | L33: Chả mực | M33: 20g
F34: Bắp cải luộc | G34: 75g-80g | I34: Đỗ cove luộc | J34: 75g-80g | L34: Thịt nướng | M34: 30g-35g
F35: Cơm trắng | G35: 200-250gr | I35: Cơm trắng | J35: 200-250gr
F36: Canh chua dứa giá | G36: 300-350gr | I36: Canh rau dền | J36: 300-350gr
F37: Sữa chua | G37: 1 hộp | I37: Cam | J37: 80g
B39: Thứ 6 | C39: Cháo thịt băm | D39: 200g-230g | F39: Cá nục kho cay | G39: 60g-80g | I39: Gà om nấm | J39: 60g-80g | L39: Xôi thịt kho trứng
C40: Trứng vịt lộn | D40: 1 quả | F40: Thịt xào măng giá | G40: Thịt 50g+ măng giá 20g | I40: Tôm chiên vừng | J40: 30g-35g | L40: Thịt | M40: 35g-40g
C41: Quẩy | D41: 1 cái | F41: Đậu sốt trắng cà chua | G41: 60g-70g | I41: Thịt băm xào đỗ cove | J41: 60g | L41: Trứng gà | M41: 1 quả
F42: Bí đỏ xào tỏi | G42: 75g-80g | I42: Rau muống luộc | J42: 75g-80g | L42: Sữa chua | M42: 1 hộp 90g
F43: Cơm trắng | G43: 200-250gr | I43: Cơm trắng | J43: 200-250gr
F44: Canh rau ngót | G44: 300-350gr | I44: Nước luộc dầm chua | J44: 300-350gr
...

Sheet THỰC ĐƠN SGC
B1: CÔNG TY: HSS
B2: THỰC ĐƠN SUẤT ĂN CA CÔNG NHÂN
B3: Dự án:
B4: (TỪ 17/08/2026 đến 23/08/2026)
B5: Thứ | C5: SÁNG | F5: TRƯA | I5: TỐI | L5: ĐÊM
C6: Món | D6: Trọng lượng thành phẩm | F6: Món | G6: Trọng lượng thành phẩm | I6: Món | J6: Trọng lượng thành phẩm | L6: Món | M6: Trọng lượng thành phẩm
B7: Thứ 2 | C7: Bánh mì kẹp | D7: 1 cái | F7: Tôm rang lá chanh | G7: 30g-35g | I7: Gà kho nghệ | J7: 60g-70g | L7: Bún riêu cua cá + giò
C8: Chả | D8: 30g-35g | F8: Thịt xào hành tây | G8: 30g-35g | I8: Thăn cá chiên xù | J8: 40g-50g | L8: Bún tươi | M8: 230g-250g
C9: Sữa fami | D9: 180ml | F9: Trứng cút rim tiêu | G9: 4 quả | I9: Chuối om thịt | J9: 60g-70g | L9: Cá chiên | M9: 30g-35g
F10: Bắp cải luộc | G10: 75g-80g | I10: Rau muống luộc | J10: 75g-80g | L10: Giò lụa | M10: 15g-20g
F11: Cơm trắng | G11: 200-250gr | I11: Cơm trắng | J11: 200-250gr
F12: Canh rau ngót | G12: 300-350gr | I12: Nước luộc dầm chua | J12: 300-350gr
F13: Ổi | G13: 80g | I13: Thanh long | J13: 80g
B15: Thứ 3 | C15: Cháo ngao | D15: 200-230g | F15: Bò nấu sốt vang | G15: 35g-40g | I15: Cá sốt cà chua | J15: 75g-80g | L15: Xôi gà đỗ xanh
C16: Trứng vịt lộn | D16: 1 quả | F16: Ức gà xào hành nấm | G16: 35g-40g | I16: Tim xào dưa | J16: 20g-25g | L16: Gà xé | M16: 30g-35g
C17: Quẩy | D17: 1 cái | F17: Đậu sốt cà chua | G17: 50g-60g | I17: Lạc chao | J17: 20g-30g | L17: Sữa chua | M17: 1 hộp95g
F18: Đỗ cove luộc | G18: 75g-80g | I18: Bí xanh luộc | J18: 75g-80g
F19: Cơm trắng | G19: 200-250gr | I19: Cơm trắng | J19: 200-250gr
F20: Canh rau dền | G20: 300-350gr | I20: Canh cải xanh | J20: 300-350gr
F21: Chuối | G21: 1 quả | I21: Dưa hấu | J21: 90g-100g
B23: Thứ 4 | C23: Bún chấm | D23: 200g-230g | F23: Gà chiên mắm | G23: 60g-70g | I23: Sườn chua ngọt | J23: 55g-60g | L23: Cháo Sườn ngô
C24: Thịt nướng | D24: 25g-30g | F24: Giò lụa rim tiêu | G24: 35g-40g | I24: Trứng đúc thịt | J24: 60g | L24: Sườn | M24: 45g-50g
F25: Mướp đắng xào trứng | G25: 60g | I25: Đậu om cà | J25: 60g | L25: Ngô ngọt | M25: 20g-25g
F26: Rau muống luộc | G26: 75g-80g | I26: Củ cải luộc | J26: 75g-80g
F27: Cơm trắng | G27: 200-250gr | I27: Cơm trắng | J27: 200-250gr
F28: Nước luộc dầm chua | G28: 300-350gr | I28: Canh rau ngót | J28: 300-350gr
F29: Cam | G29: 80g | I29: Ổi | J29: 80g
B31: Thứ 5 | C31: Xôi giò rim | D31: 180g-200g | F31: Vịt om sấu khoai môn | G31: 50g-55g | I31: Bò kho củ cải | J31: 35g-40g | L31: Bánh cuốn chả mực + thịt nướng
C32: Sữa fami | D32: 180ml | F32: Thịt xào su su | G32: 30g-35g | I32: Chả cá sốt thì là | J32: 40g-45g | L32: Bánh cuốn | M32: 230g-250g
F33: Lạc chao | G33: 20g-25g | I33: Thịt băm om chuối | J33: 60g | L33: Chả mực | M33: 20g
F34: Bắp cải luộc | G34: 75g-80g | I34: Đỗ cove luộc | J34: 75g-80g | L34: Thịt nướng | M34: 30g-35g
F35: Cơm trắng | G35: 200-250gr | I35: Cơm trắng | J35: 200-250gr
F36: Canh chua dứa giá | G36: 300-350gr | I36: Canh rau dền | J36: 300-350gr
F37: Sữa chua | G37: 1 hộp | I37: Cam | J37: 80g
B39: Thứ 6 | C39: Cháo thịt băm | D39: 200g-230g | F39: Cá nục kho cay | G39: 60g-70g | I39: Gà om nấm | J39: 60g-70g | L39: Xôi thịt kho trứng
C40: Trứng vịt lộn | D40: 1 quả | F40: Thịt xào măng giá | G40: 30g-35g | I40: Giò lụa rim | J40: 35g-40g | L40: Thịt | M40: 35g-40g
C41: Quẩy | D41: 1 cái | F41: Đậu sốt trắng cà chua | G41: 60g-70g | I41: Thịt băm xào đỗ cove | J41: 40g-50g | L41: Trứng gà | M41: 1 quả
F42: Bí đỏ xào tỏi | G42: 75g-80g | I42: Rau muống luộc | J42: 75g-80g
F43: Cơm trắng | G43: 200-250gr | I43: Cơm trắng | J43: 200-250gr
F44: Canh rau ngót | G44: 300-350gr | I44: Nước luộc dầm chua | J44: 300-350gr
...

Sheet Thứ 2
A2: Bữa Sáng 20.000Đ vin alpha
A3: Cơ cấu | B3: Món ăn | C3: Mã hàng | D3: Nguyên liệu | E3: Định lượng sống | F3: Số suất | G3: Gọi hàng | H3: Đơn giá | I3: Thành tiền | J3: Tổng
B4: bánh bao trứng luộc sữa fami | C4: NLG0043 | D4: Bánh bao thập cẩm 180g/cái | E4: 1000 | F4: 600 | G4: =E4*F4/1000 | H4: 11000 | I4: =IFERROR(E4*H4/1000,"") | J4: =I4
C5: NLT0181 | D5: trứng gà cn | E5: 1000 | F5: 600 | G5: =E5*F5/1000 | H5: 2300 | I5: =IFERROR(E5*H5/1000,"") | J5: =I5
C6: HHS0051 | D6: sữa fami bịch | E6: 1000 | F6: 600 | G6: =E6*F6/1000 | H6: 3400 | I6: =IFERROR(E6*H6/1000,"") | J6: =I6
A7: Gia vị | J7: 800
D8: GAS | J8: 1250 | O8: =850+400+430
D9: Chi phí đũa thìa +điện nước | J9: 2500
A10: Tổng chi phí TĐ 1 | J10: =SUM(J4:J9)
A11: Cost TĐ 1 | J11: =J10/20000
A16: Bữa Sáng 20.000Đ sgc
A17: Cơ cấu | B17: Món ăn | C17: Mã hàng | D17: Nguyên liệu | E17: Định lượng sống | F17: Số suất | G17: Gọi hàng | H17: Đơn giá | I17: Thành tiền | J17: Tổng
B18: bánh mì kẹp chả sữa fami | D18: bánh mì | E18: 1000 | F18: 1600 | G18: =E18*F18/1000 | H18: 3500 | I18: =IFERROR(E18*H18/1000,"") | J18: =I18
C19: NLT0003 | D19: chả lợn | E19: 40 | F19: 1600 | G19: =E19*F19/1000 | H19: 85000 | I19: =IFERROR(E19*H19/1000,"") | J19: =I19
C20: NLR0060 | D20: dưa chuột | E20: 40 | F20: 1600 | G20: =E20*F20/1000 | H20: 15000 | I20: =IFERROR(E20*H20/1000,"") | J20: =I20
C21: NLR0153 | D21: rau mùi ta | E21: 5 | F21: 1600 | G21: =E21*F21/1000 | H21: 15000 | I21: =IFERROR(E21*H21/1000,"") | J21: =I21
C22: HHS0051 | D22: sữa fami bịch | E22: 1000 | F22: 1600 | G22: =E22*F22/1000 | H22: 3400 | I22: =IFERROR(E22*H22/1000,"") | J22: =I22
A23: Gia vị | J23: 800
D24: GAS | J24: 1250 | O24: =850+400+430
D25: Chi phí đũa thìa +điện nước | J25: 2500
A26: Tổng chi phí TĐ 1 | J26: =SUM(J18:J25)
A27: Cost TĐ 1 | J27: =J26/20000
A35: CHIẾT TÍNH THỰC ĐƠN CA Trưa 40.000đ
A36: Cơ cấu | B36: Món ăn | C36: Mã hàng | D36: Nguyên liệu | E36: Định lượng sống | F36: Số suất | G36: Gọi hàng | H36: Đơn giá | I36: Thành tiền | J36: Tổng
B37: tôm rang lá chanh | C37: NLS0081 | D37: Tôm dảo tươi 100-120 | E37: 50 | F37: 2200 | G37: =E37*F37/1000 | H37: 147000 | I37: =IFERROR(E37*H37/1000,"") | J37: =I37
C38: NLR0102 | D38: lá chanh | E38: 0.5 | F38: 2200 | G38: =E38*F38/1000 | H38: 55000 | I38: =IFERROR(E38*H38/1000,"") | J38: =I38
B39: thịt xào hành tây | C39: NLT0076 | D39: thịt lợn mông sấn | E39: 80 | F39: 2200 | G39: =E39*F39/1000 | H39: 101000 | I39: =IFERROR(E39*H39/1000,"") | J39: =I39
C40: NLR0083 | D40: hành tây | E40: 30 | F40: 2200 | G40: =E40*F40/1000 | H40: 9000 | I40: =IFERROR(E40*H40/1000,"") | J40: =I40
C41: NLR0018 | D41: cà rốt | E41: 10 | F41: 2200 | G41: =E41*F41/1000 | H41: 11000 | I41: =IFERROR(E41*H41/1000,"") | J41: =I41
B42: trứng cút rim tiêu | C42: NLT0100 | D42: trứng cút bóc vỏ | E42: 4000 | F42: 2200 | G42: =E42*F42/1000 | H42: 850 | I42: =IFERROR(E42*H42/1000,"") | J42: =I42
B43: bắp cải luộc | C43: NLR0001 | D43: bắp cải trắng | E43: 120 | F43: 2200 | G43: =E43*F43/1000 | H43: 9000 | I43: =IFERROR(E43*H43/1000,"") | J43: =I43
B44: cơm trắng | C44: NLG0013 | D44: gạo bắc hương | E44: 180 | F44: 2200 | G44: =E44*F44/1000 | H44: 13800 | I44: =IFERROR(E44*H44/1000,"") | J44: =I44
B45: canh rau ngót | C45: NLR0157 | D45: rau ngót | E45: 10 | F45: 2200 | G45: =E45*F45/1000 | H45: 17000 | I45: =IFERROR(E45*H45/1000,"") | J45: =I45
B46: ổi | C46: NLQ0016 | D46: Quả ổi 3-5 quả/kg | E46: 100 | F46: 2200 | G46: =E46*F46/1000 | H46: 10000 | I46: =IFERROR(E46*H46/1000,"") | J46: =I46
A47: Gia vị | J47: =(40000*4)/100
D48: Gas | J48: 2500
D49: Chi phí đũa thìa + điện nước | J49: 2500
A50: Tổng chi phí TĐ 1 | J50: =SUM(J37:J49)
A51: Cost TĐ 1 | J51: =J50/40000
A53: THỰC ĐƠN CA Chiều 40.000Đ
...

Sheet Thứ 3
A2: Bữa Sáng 20.000Đ | G2: a
A3: Cơ cấu | B3: Món ăn | C3: Mã hàng | D3: Nguyên liệu | E3: Định lượng sống | F3: Số suất | G3: Gọi hàng | H3: Đơn giá | I3: Thành tiền | J3: Tổng
B4: cháo ngao trứng vịt lộn quẩy | C4: NLG0013 | D4: gạo bắc hương | E4: 45 | F4: 2030 | G4: =E4*F4/1000 | H4: 13800 | I4: =IFERROR(E4*H4/1000,"") | J4: =I4
C5: NLG0006 | D5: gạo nếp | E5: 5 | F5: 2030 | G5: =E5*F5/1000 | H5: 35000 | I5: =IFERROR(E5*H5/1000,"") | J5: =I5
C6: NLS0058 | D6: ngao | E6: 70 | F6: 2030 | G6: =E6*F6/1000 | H6: 24000 | I6: =IFERROR(E6*H6/1000,"") | J6: =I6
C7: NPG0066 | D7: hành khô | E7: 5 | F7: 2030 | G7: =E7*F7/1000 | H7: 22000 | I7: =IFERROR(E7*H7/1000,"") | J7: =I7
C8: NLR0079 | D8: hành lá | E8: 3 | F8: 2030 | G8: =E8*F8/1000 | H8: 14000 | I8: =IFERROR(E8*H8/1000,"") | J8: =I8
C9: NLR0170 | D9: tía tô | E9: 1 | F9: 2030 | G9: =E9*F9/1000 | H9: 25000 | I9: =IFERROR(E9*H9/1000,"") | J9: =I9
C10: NLT0105 | D10: trứng vịt lộn | E10: 1100 | F10: 2030 | G10: =E10*F10/1000 | H10: 3900 | I10: =IFERROR(E10*H10/1000,"") | J10: =I10
C11: NPG0361 | D11: quẩy | E11: 1300 | F11: 2030 | G11: =E11*F11/1000 | H11: 1300 | I11: =IFERROR(E11*H11/1000,"") | J11: =I11
A12: Gia vị | J12: 800
D13: GAS | J13: 1250
D14: Chi phí khay,đũa | J14: 1600
A15: Tổng chi phí TĐ 1 | J15: =SUM(J4:J14)
A16: Cost TĐ 1 | J16: =J15/20000
A26: CHIẾT TÍNH THỰC ĐƠN CA Trưa 40.000đ
A27: Cơ cấu | B27: Món ăn | C27: Mã hàng | D27: Nguyên liệu | E27: Định lượng sống | F27: Số suất | G27: Gọi hàng | H27: Đơn giá | I27: Thành tiền | J27: Tổng
B28: bò nấu sốt vang | C28: NLT0435 | D28: Thịt dẻ sườn trâu 123 | E28: 65 | F28: 2100 | G28: =E28*F28/1000 | H28: 120000 | I28: =IFERROR(E28*H28/1000,"") | J28: =I28
C29: NLR0100 | D29: khoai tây | E29: 40 | F29: 2100 | G29: =E29*F29/1000 | H29: 13000 | I29: =IFERROR(E29*H29/1000,"") | J29: =I29
C30: NLR0018 | D30: cà rốt | E30: 10 | F30: 2100 | G30: =E30*F30/1000 | H30: 11000 | I30: =IFERROR(E30*H30/1000,"") | J30: =I30
C31: NLR0153 | D31: rau mùi ta | E31: 1 | F31: 2100 | G31: =E31*F31/1000 | H31: 15000 | I31: =IFERROR(E31*H31/1000,"") | J31: =I31
B32: ức gà xào hành nấm | C32: NLT0107 | D32: Ức gà không xương | E32: 70 | F32: 2100 | G32: =E32*F32/1000 | H32: 57000 | I32: =IFERROR(E32*H32/1000,"") | J32: =I32
C33: NLR0546 | D33: nấm hương khô | E33: 1 | F33: 2100 | G33: =E33*F33/1000 | H33: 200000 | I33: =IFERROR(E33*H33/1000,"") | J33: =I33
C34: NLR0083 | D34: hành tây | E34: 20 | F34: 2100 | G34: =E34*F34/1000 | H34: 9000 | I34: =IFERROR(E34*H34/1000,"") | J34: =I34
C35: NLR0018 | D35: cà rốt | E35: 10 | F35: 2100 | G35: =E35*F35/1000 | H35: 11000 | I35: =IFERROR(E35*H35/1000,"") | J35: =I35
B36: đậu sốt cà chua | C36: NLT0011 | D36: đậu phụ kg | E36: 100 | F36: 2100 | G36: =E36*F36/1000 | H36: 17000 | I36: =IFERROR(E36*H36/1000,"") | J36: =I36
C37: NLR0268 | D37: cà chua to | E37: 10 | F37: 2100 | G37: =E37*F37/1000 | H37: 22000 | I37: =IFERROR(E37*H37/1000,"") | J37: =I37
B38: đỗ cove luộc | C38: NLR0068 | D38: đậu cô ve | E38: 100 | F38: 2100 | G38: =E38*F38/1000 | H38: 18000 | I38: =IFERROR(E38*H38/1000,"") | J38: =I38
B39: cơm trắng | C39: NLG0013 | D39: gạo bắc hương | E39: 180 | F39: 2100 | G39: =E39*F39/1000 | H39: 13800 | I39: =IFERROR(E39*H39/1000,"") | J39: =I39
B40: canh rau dền | C40: NLR0148 | D40: rau dền | E40: 15 | F40: 2100 | G40: =E40*F40/1000 | H40: 11000 | I40: =IFERROR(E40*H40/1000,"") | J40: =I40
B41: chuối | C41: NLQ0011 | D41: Qủa Chuối tiêu chín | E41: 1000 | F41: 2100 | G41: =E41*F41/1000 | H41: 1500 | I41: =IFERROR(E41*H41/1000,"") | J41: =I41
A42: Gia vị | J42: 1600
D43: Gas | J43: 2500
D44: Chi phí đũa thìa + điện nước | J44: 2700
A45: Tổng chi phí TĐ 1 | J45: =SUM(J28:J44)
A46: Cost TĐ 1 | J46: =J45/40000
A49: THỰC ĐƠN CA Chiều 40.000Đ
A50: Cơ cấu | B50: Món ăn | C50: Mã hàng | D50: Nguyên liệu | E50: Định lượng sống | F50: Số suất | G50: Gọi hàng | H50: Đơn giá | I50: Thành tiền | J50: Tổng
B51: cá sốt cà chua | C51: NLS0491 | D51: Cá chim sơ chế bỏ đầu 0,8-1,5kg/con | E51: 130 | F51: 2000 | G51: =E51*F51/1000 | H51: 47000 | I51: =IFERROR(E51*H51/1000,"") | J51: =I51
C52: NLR0268 | D52: cà chua to | E52: 10 | F52: 2000 | G52: =E52*F52/1000 | H52: 22000 | I52: =IFERROR(E52*H52/1000,"") | J52: =I52
...

Sheet Thứ 4
A1: THỨ 4 NGÀY 23/6
A2: Bữa Sáng 20.000Đ
A3: Cơ cấu | B3: Món ăn | C3: Mã hàng | D3: Nguyên liệu | E3: Định lượng sống | F3: Số suất | G3: Gọi hàng | H3: Đơn giá | I3: Thành tiền | J3: Tổng
B4: bún chấm thịt nướng | C4: NLG0001 | D4: bún | E4: 235 | F4: 2100 | G4: =E4*F4/1000 | H4: 17000 | I4: =IFERROR(E4*H4/1000,"") | J4: =I4
C5: NLT0076 | D5: thịt lợn mông sấn | E5: 60 | F5: 2100 | G5: =E5*F5/1000 | H5: 101000 | I5: =IFERROR(E5*H5/1000,"") | J5: =I5
C6: NLR0175 | D6: sả củ | E6: 2 | F6: 2100 | G6: =E6*F6/1000 | H6: 15000 | I6: =IFERROR(E6*H6/1000,"") | J6: =I6
C7: NLR0092 | D7: kinh giới | E7: 3 | F7: 2100 | G7: =E7*F7/1000 | H7: 19000 | I7: =IFERROR(E7*H7/1000,"") | J7: =I7
C8: NLR0144 | D8: húng bạc hà | E8: 3 | F8: 2100 | G8: =E8*F8/1000 | H8: 30000 | I8: =IFERROR(E8*H8/1000,"") | J8: =I8
C9: NLR0162 | D9: Rau xà lách | E9: 3 | F9: 2100 | G9: =E9*F9/1000 | H9: 16000 | I9: =IFERROR(E9*H9/1000,"") | J9: =I9
C10: NLR0170 | D10: tía tô | E10: 3 | F10: 2100 | G10: =E10*F10/1000 | H10: 25000 | I10: =IFERROR(E10*H10/1000,"") | J10: =I10
A11: Gia vị | J11: 800
D12: GAS | J12: 1250
D13: Chi phí khay,đũa | J13: 1600
A14: Tổng chi phí TĐ 1 | J14: =SUM(J4:J13)
A15: Cost TĐ 1 | J15: =J14/20000
A28: CA Trưa 40.000đ
A29: Cơ cấu | B29: Món ăn | C29: Mã hàng | D29: Nguyên liệu | E29: Định lượng sống | F29: Số suất | G29: Gọi hàng | H29: Đơn giá | I29: Thành tiền | J29: Tổng
B30: gà chiên mắm | C30: NLT0063 | D30: Thịt gà cn không đầu | E30: 120 | F30: 2200 | G30: =E30*F30/1000 | H30: 48000 | I30: =IFERROR(E30*H30/1000,"") | J30: =I30
C31: NLR0102 | D31: lá chanh | E31: 0.2 | F31: 2200 | G31: =E31*F31/1000 | H31: 55000 | I31: =IFERROR(E31*H31/1000,"") | J31: =I31
A32: VIN ALPHA | B32: tôm rimme | C32: NLS0081 | D32: Tôm dảo tươi 100-120 | E32: 50 | F32: 2200 | G32: =E32*F32/1000 | H32: 147000 | I32: =IFERROR(E32*H32/1000,"") | J32: =I32
C33: NPG0094 | D33: me khô | E33: 1 | F33: 2200 | G33: =E33*F33/1000 | H33: 30000 | I33: =IFERROR(E33*H33/1000,"") | J33: =I33
B34: mướp đắng xào trứng | C34: NLR0117 | D34: mướp đắng | E34: 60 | F34: 2200 | G34: =E34*F34/1000 | H34: 15000 | I34: =IFERROR(E34*H34/1000,"") | J34: =I34
C35: NLT0181 | D35: trứng gà cn | E35: 400 | F35: 2200 | G35: =E35*F35/1000 | H35: 2300 | I35: =IFERROR(E35*H35/1000,"") | J35: =I35
B36: rau muống luộc | C36: NLR0156 | D36: rau muống cắt gốc | E36: 110 | F36: 2200 | G36: =E36*F36/1000 | H36: 9000 | I36: =IFERROR(E36*H36/1000,"") | J36: =I36
B37: cơm trắng | C37: NLG0013 | D37: gạo bắc hương | E37: 180 | F37: 2200 | G37: =E37*F37/1000 | H37: 13800 | I37: =IFERROR(E37*H37/1000,"") | J37: =I37
B38: nước luộc dầm chua | C38: NLR0142 | D38: Quả sấu | E38: 5 | F38: 2200 | G38: =E38*F38/1000 | H38: 23000 | I38: =IFERROR(E38*H38/1000,"") | J38: =I38
B39: cam | C39: NLQ0006 | D39: quả cam | E39: 110 | F39: 2200 | G39: =E39*F39/1000 | H39: 18000 | I39: =IFERROR(E39*H39/1000,"") | J39: =I39
A40: Gia vị | J40: 1600
D41: Gas | J41: 2500
D42: Chi Phí khay, đũa | J42: 2500
A43: Tổng chi phí TĐ 1 | J43: =SUM(J30:J42)
A44: Cost TĐ 1 | J44: =J43/40000
A46: CA CHIỀU 40.000Đ
A47: Cơ cấu | B47: Món ăn | C47: Mã hàng | D47: Nguyên liệu | E47: Định lượng sống | F47: Số suất | G47: Gọi hàng | H47: Đơn giá | I47: Thành tiền | J47: Tổng
B48: sườn chua ngọt | C48: NLT0445 | D48: Sườn cánh buồm ĐL | E48: 110 | F48: 2100 | G48: =E48*F48/1000 | H48: 83000 | I48: =IFERROR(E48*H48/1000,"") | J48: =I48
C49: NLR0083 | D49: hành tây | E49: 20 | F49: 2100 | G49: =E49*F49/1000 | H49: 9000 | I49: =IFERROR(E49*H49/1000,"") | J49: =I49
B50: trứng đúc thịt | C50: NLT0181 | D50: trứng gà cn | E50: 900 | F50: 2100 | G50: =E50*F50/1000 | H50: 2300 | I50: =IFERROR(E50*H50/1000,"") | J50: =I50
C51: NLT0076 | D51: thịt lợn mông sấn | E51: 30 | F51: 2100 | G51: =E51*F51/1000 | H51: 101000 | I51: =IFERROR(E51*H51/1000,"") | J51: =I51
B52: đậu om cà | C52: NLT0011 | D52: đậu phụ kg | E52: 40 | F52: 2100 | G52: =E52*F52/1000 | H52: 17000 | I52: =IFERROR(E52*H52/1000,"") | J52: =I52
C53: NLR0024 | D53: cà tím dài | E53: 60 | F53: 2100 | G53: =E53*F53/1000 | H53: 8000 | I53: =IFERROR(E53*H53/1000,"") | J53: =I53
...

Sheet Thứ 5
A2: THỨ 5 NGÀY 24/6
A3: Bữa Sáng 20.000Đ
A4: Cơ cấu | B4: Món ăn | C4: Mã hàng | D4: Nguyên liệu | E4: Định lượng sống | F4: Số suất | G4: Gọi hàng | H4: Đơn giá | I4: Thành tiền | J4: Tổng
B5: xôi giò rim sữa fami ( Bên vinalpha dưa góp đóng hộp để riêng) | C5: NLG0006 | D5: gạo nếp | E5: 150 | F5: 2200 | G5: =E5*F5/1000 | H5: 35000 | I5: =IFERROR(E5*H5/1000,"") | J5: =I5 | K5: 250g/cái | L5: =+(J29+J54+J72)/3
C6: NLT0017 | D6: giò lụa | E6: 40 | F6: 2200 | G6: =E6*F6/1000 | H6: 85000 | I6: =IFERROR(E6*H6/1000,"") | J6: =I6
C7: NPG0066 | D7: hành khô | E7: 5 | F7: 2200 | G7: =E7*F7/1000 | H7: 22000 | I7: =IFERROR(E7*H7/1000,"") | J7: =I7
C8: NLR0060 | D8: dưa chuột | E8: 40 | F8: 2200 | G8: =E8*F8/1000 | H8: 15000 | I8: =IFERROR(E8*H8/1000,"") | J8: =I8
C9: NLR0018 | D9: cà rốt | E9: 5 | F9: 2200 | G9: =E9*F9/1000 | H9: 11000 | I9: =IFERROR(E9*H9/1000,"") | J9: =I9
C10: NLR0154 | D10: rau mùi tàu | E10: 1 | F10: 2200 | G10: =E10*F10/1000 | H10: 25000 | I10: =IFERROR(E10*H10/1000,"") | J10: =I10
C11: HHS0051 | D11: sữa fami bịch | E11: 1000 | F11: 2200 | G11: =E11*F11/1000 | H11: 3400 | I11: =IFERROR(E11*H11/1000,"") | J11: =I11
A12: Gia vị | J12: 800
D13: GAS | J13: 1000
D14: Chi phí khay,đũa | J14: 1500
A16: Tổng chi phí TĐ 1 | J16: =SUM(J5:J14)
A17: Cost TĐ 1 | J17: =J16/20000
A19: CHIẾT TÍNH THỰC ĐƠN CA Trưa 40.000đ
A20: Cơ cấu | B20: Món ăn | C20: Mã hàng | D20: Nguyên liệu | E20: Định lượng sống | F20: Số suất | G20: Gọi hàng | H20: Đơn giá | I20: Thành tiền | J20: Tổng
B21: vịt om sấu khoai môn | C21: NLT0094 | D21: Thịt vịt sơ chế bỏ đầu, cổ cánh 2-2.5kg/con. | E21: 110 | F21: 2250 | G21: =E21*F21/1000 | H21: 85000 | I21: =IFERROR(E21*H21/1000,"") | J21: =I21
C22: NLR0244 | D22: khoai môn sc | E22: 35 | F22: 2250 | G22: =E22*F22/1000 | H22: 30000 | I22: =IFERROR(E22*H22/1000,"") | J22: =I22
C23: NLR0142 | D23: quả sấu | E23: 3 | F23: 2250 | G23: =E23*F23/1000 | H23: 23000 | I23: =IFERROR(E23*H23/1000,"") | J23: =I23
C24: NLR0154 | D24: rau mùi tàu | E24: 1 | F24: 2250 | G24: =E24*F24/1000 | H24: 25000 | I24: =IFERROR(E24*H24/1000,"") | J24: =I24
B25: thịt xào su su | C25: NLT0076 | D25: thịt lợn mông sấn | E25: 75 | F25: 2250 | G25: =E25*F25/1000 | H25: 101000 | I25: =IFERROR(E25*H25/1000,"") | J25: =I25
C26: NLR0165 | D26: su su | E26: 40 | F26: 2250 | G26: =E26*F26/1000 | H26: 9000 | I26: =IFERROR(E26*H26/1000,"") | J26: =I26
C27: NLR0018 | D27: cà rốt | E27: 10 | F27: 2250 | G27: =E27*F27/1000 | H27: 11000 | I27: =IFERROR(E27*H27/1000,"") | J27: =I27
B28: lạc chao | C28: NLT0020 | D28: lạc nhân | E28: 35 | F28: 2250 | G28: =E28*F28/1000 | H28: 50000 | I28: =IFERROR(E28*H28/1000,"") | J28: =I28
B29: bắp cải luộc | C29: NLR0001 | D29: bắp cải trắng | E29: 120 | F29: 2250 | G29: =E29*F29/1000 | H29: 9000 | I29: =IFERROR(E29*H29/1000,"") | J29: =I29
B30: cơm trắng | C30: NLG0013 | D30: gạo bắc hương | E30: 180 | F30: 2250 | G30: =E30*F30/1000 | H30: 13800 | I30: =IFERROR(E30*H30/1000,"") | J30: =I30
B31: canh chua dứa giá | C31: NLR0058 | D31: Dứa chín sơ chế (kg) | E31: 10 | F31: 2250 | G31: =E31*F31/1000 | H31: 28000 | I31: =IFERROR(E31*H31/1000,"") | J31: =I31
C32: NLR0076 | D32: giá đỗ | E32: 10 | F32: 2250 | G32: =E32*F32/1000 | H32: 10000 | I32: =IFERROR(E32*H32/1000,"") | J32: =I32
C33: NLR0268 | D33: cà chua to | E33: 3 | F33: 2250 | G33: =E33*F33/1000 | H33: 22000 | I33: =IFERROR(E33*H33/1000,"") | J33: =I33
B34: sữa chua | C34: HHS0101 | D34: Sữa chua elovi 95g *48 hộp/thùng | E34: 100 | F34: 2250 | G34: =E34*F34/1000 | H34: 3432 | I34: =IFERROR(E34*H34/1000,"") | J34: =I34
A35: Gia vị | J35: 1600
D36: Gas | J36: 2500
D37: Chi Phí khay, đũa | J37: 2500
A38: Tổng chi phí TĐ 1 | J38: =SUM(J21:J37)
A39: Cost TĐ 1 | J39: =J38/40000
A41: THỰC ĐƠN CA Chiều 40.000Đ
A42: Cơ cấu | B42: Món ăn | C42: Mã hàng | D42: Nguyên liệu | E42: Định lượng sống | F42: Số suất | G42: Gọi hàng | H42: Đơn giá | I42: Thành tiền | J42: Tổng
B43: bò kho củ cải | C43: NLT0435 | D43: Thịt dẻ sườn trâu 123 | E43: 70 | F43: 2120 | G43: =E43*F43/1000 | H43: 120000 | I43: =IFERROR(E43*H43/1000,"") | J43: =I43
C44: NLR0044 | D44: củ cải | E44: 35 | F44: 2120 | G44: =E44*F44/1000 | H44: 8000 | I44: =IFERROR(E44*H44/1000,"") | J44: =I44
...

Sheet Thứ 6
A2: Bữa Sáng 20.000Đ | G2: a
A3: Cơ cấu | B3: Món ăn | C3: Mã hàng | D3: Nguyên liệu | E3: Định lượng sống | F3: Số suất | G3: Gọi hàng | H3: Đơn giá | I3: Thành tiền | J3: Tổng
B4: cháo thịt băm trứng vịt lộn quẩy | C4: NLG0005 | D4: gạo khang dân | E4: 45 | F4: 2150 | G4: =E4*F4/1000 | H4: 12500 | I4: =IFERROR(E4*H4/1000,"") | J4: =I4
C5: NLG0006 | D5: gạo nếp | E5: 5 | F5: 2150 | G5: =E5*F5/1000 | H5: 35000 | I5: =IFERROR(E5*H5/1000,"") | J5: =I5
D6: thịt lợn mông sấn | E6: 40 | F6: 2150 | G6: =E6*F6/1000 | H6: 35000 | I6: =IFERROR(E6*H6/1000,"") | J6: =I6
C7: NPG0066 | D7: hành khô | E7: 5 | F7: 2150 | G7: =E7*F7/1000 | H7: 22000 | I7: =IFERROR(E7*H7/1000,"") | J7: =I7
C8: NLR0079 | D8: hành lá | E8: 3 | F8: 2150 | G8: =E8*F8/1000 | H8: 14000 | I8: =IFERROR(E8*H8/1000,"") | J8: =I8
C9: NLR0154 | D9: rau mùi tàu | E9: 1 | F9: 2150 | G9: =E9*F9/1000 | H9: 25000 | I9: =IFERROR(E9*H9/1000,"") | J9: =I9
C10: NLT0105 | D10: trứng vịt lộn | E10: 1100 | F10: 2150 | G10: =E10*F10/1000 | H10: 3900 | I10: =IFERROR(E10*H10/1000,"") | J10: =I10
C11: NPG0361 | D11: quẩy | E11: 1300 | F11: 2150 | G11: =E11*F11/1000 | H11: 1300 | I11: =IFERROR(E11*H11/1000,"") | J11: =I11
A12: Gia vị | J12: 800
D13: GAS | J13: 1250
D14: Chi phí khay,đũa | J14: 2500
A15: Tổng chi phí TĐ 1 | J15: =SUM(J4:J14)
A16: Cost TĐ 1 | J16: =J15/20000
A19: CHIẾT TÍNH THỰC ĐƠN CA Trưa 40.000đ
A20: Cơ cấu | B20: Món ăn | C20: Mã hàng | D20: Nguyên liệu | E20: Định lượng sống | F20: Số suất | G20: Gọi hàng | H20: Đơn giá | I20: Thành tiền | J20: Tổng
B21: cá nục kho cay | C21: NLT0501 | D21: Cá nục gai sơ chế bỏ đầu | E21: 170 | F21: 2200 | G21: =E21*F21/1000 | H21: 44000 | I21: =IFERROR(E21*H21/1000,"") | J21: =I21
C22: NLR0175 | D22: sả củ | E22: 3 | F22: 2200 | G22: =E22*F22/1000 | H22: 15000 | I22: =IFERROR(E22*H22/1000,"") | J22: =I22
C23: NLR0073 | D23: gừng củ | E23: 2 | F23: 2200 | G23: =E23*F23/1000 | H23: 22000 | I23: =IFERROR(E23*H23/1000,"") | J23: =I23
B24: thịt xào măng giá | C24: NLT0076 | D24: thịt lợn mông sấn | E24: 70 | F24: 2200 | G24: =E24*F24/1000 | H24: 101000 | I24: =IFERROR(E24*H24/1000,"") | J24: =I24
C25: NLR0111 | D25: măng lá | E25: 30 | F25: 2200 | G25: =E25*F25/1000 | H25: 31000 | I25: =IFERROR(E25*H25/1000,"") | J25: =I25
C26: NLR0076 | D26: giá đỗ | E26: 20 | F26: 2200 | G26: =E26*F26/1000 | H26: 10000 | I26: =IFERROR(E26*H26/1000,"") | J26: =I26
C27: NLR0154 | D27: rau mùi tàu | E27: 1 | F27: 2200 | G27: =E27*F27/1000 | H27: 25000 | I27: =IFERROR(E27*H27/1000,"") | J27: =I27
B28: đậu sốt cà chua | C28: NLT0011 | D28: đậu phụ kg | E28: 95 | F28: 2200 | G28: =E28*F28/1000 | H28: 17000 | I28: =IFERROR(E28*H28/1000,"") | J28: =I28
C29: NLR0268 | D29: cà chua to | E29: 5 | F29: 2200 | G29: =E29*F29/1000 | H29: 22000 | I29: =IFERROR(E29*H29/1000,"") | J29: =I29
B30: Cải ngọt luộc | D30: cải ngọt cắt gốc | E30: 120 | F30: 2200 | G30: =E30*F30/1000 | H30: 10000 | I30: =IFERROR(E30*H30/1000,"") | J30: =I30
B31: cơm trắng | C31: NLG0013 | D31: gạo bắc hương | E31: 180 | F31: 2200 | G31: =E31*F31/1000 | H31: 13800 | I31: =IFERROR(E31*H31/1000,"") | J31: =I31 | O31: =95+85
B32: canh rau ngót | C32: NLR0157 | D32: Rau ngót | E32: 10 | F32: 2200 | G32: =E32*F32/1000 | H32: 17000 | I32: =IFERROR(E32*H32/1000,"") | J32: =I32 | O32: =79*25
B33: chuối | C33: NLQ0011 | D33: Qủa Chuối tiêu chín | E33: 1000 | F33: 2200 | G33: =E33*F33/1000 | H33: 1500 | I33: =IFERROR(E33*H33/1000,"") | J33: =I33
A34: Gia vị | J34: 1600
D35: Gas | J35: 2500
D36: Chi phí đũa thìa + điện nước | J36: 2500
A37: Tổng chi phí TĐ 1 | J37: =SUM(J21:J36)
A38: Cost TĐ 1 | J38: =J37/40000
A40: THỰC ĐƠN CA Chiều 40.000Đ
A41: Cơ cấu | B41: Món ăn | C41: Mã hàng | D41: Nguyên liệu | E41: Định lượng sống | F41: Số suất | G41: Gọi hàng | H41: Đơn giá | I41: Thành tiền | J41: Tổng
B42: gà om nấm | C42: NLT0063 | D42: Thịt gà CN không đầu | E42: 135 | F42: 2100 | G42: =E42*F42/1000 | H42: 48000 | I42: =IFERROR(E42*H42/1000,"") | J42: =I42
C43: NLR0546 | D43: nấm hương khô | E43: 10 | F43: 2100 | G43: =E43*F43/1000 | H43: 200000 | I43: =IFERROR(E43*H43/1000,"") | J43: =I43
A44: vin alpha | B44: tôm chiên vừng | C44: NLS0081 | D44: Tôm dảo tươi 100-120 | E44: 130 | F44: 600 | G44: =E44*F44/1000 | H44: 147000 | I44: =IFERROR(E44*H44/1000,"") | J44: =I44
...

Sheet Thứ 7
A2: Bữa Sáng 20.000Đ vinalfa | G2: a
A3: Cơ cấu | B3: Món ăn | C3: Mã hàng | D3: Nguyên liệu | E3: Định lượng sống | F3: Số suất | G3: Gọi hàng | H3: Đơn giá | I3: Thành tiền | J3: Tổng
B4: bánh cuốn chả quế | C4: NLG0043 | D4: bánh cuốn | E4: 230 | F4: 650 | G4: =E4*F4/1000 | H4: 30000 | I4: =IFERROR(E4*H4/1000,"") | J4: =I4
C5: NLT0164 | D5: chả quế | E5: 40 | F5: 650 | G5: =E5*F5/1000 | H5: 90000 | I5: =IFERROR(E5*H5/1000,"") | J5: =I5
C6: NLR0162 | D6: rau xà lách | E6: 3 | F6: 650 | G6: =E6*F6/1000 | H6: 16000 | I6: =IFERROR(E6*H6/1000,"") | J6: =I6
C7: NLR0092 | D7: kinh giới | E7: 3 | F7: 650 | G7: =E7*F7/1000 | H7: 19000 | I7: =IFERROR(E7*H7/1000,"") | J7: =I7
C8: NLR0170 | D8: tía tô | E8: 3 | F8: 650 | G8: =E8*F8/1000 | H8: 25000 | I8: =IFERROR(E8*H8/1000,"") | J8: =I8
C9: NLR0144 | D9: húng bạc hà | E9: 2 | F9: 650 | G9: =E9*F9/1000 | H9: 30000 | I9: =IFERROR(E9*H9/1000,"") | J9: =I9
C10: NPG0066 | D10: hành khô | E10: 5 | F10: 650 | G10: =E10*F10/1000 | H10: 22000 | I10: =IFERROR(E10*H10/1000,"") | J10: =I10
A11: Gia vị | J11: 800
D12: GAS | J12: 1250
D13: Chi phí khay,đũa | J13: 1600
A14: Tổng chi phí TĐ 1 | J14: =SUM(J4:J13)
A15: Cost TĐ 1 | J15: =J14/20000
A18: Bữa Sáng 20.000Đ SGC | G18: a
A19: Cơ cấu | B19: Món ăn | C19: Mã hàng | D19: Nguyên liệu | E19: Định lượng sống | F19: Số suất | G19: Gọi hàng | H19: Đơn giá | I19: Thành tiền | J19: Tổng
B20: bánh mì kẹp trứng xúc xích | D20: bánh mì | E20: 1000 | F20: 1500 | G20: =E20*F20/1000 | H20: 3500 | I20: =IFERROR(E20*H20/1000,"") | J20: =I20
C21: NLT0181 | D21: trứng gà cn | E21: 500 | F21: 1500 | G21: =E21*F21/1000 | H21: 2300 | I21: =IFERROR(E21*H21/1000,"") | J21: =I21
C22: NLT0108 | D22: Xúc xích Đức Việt 500g/gói (1 gói 10 cái) | E22: 50 | F22: 1500 | G22: =E22*F22/1000 | H22: 65000 | I22: =IFERROR(E22*H22/1000,"") | J22: =I22
C23: NLR0060 | D23: dưa chuột | E23: 50 | F23: 1500 | G23: =E23*F23/1000 | H23: 15000 | I23: =IFERROR(E23*H23/1000,"") | J23: =I23
C24: NLR0153 | D24: rau mùi ta | E24: 2 | F24: 1500 | G24: =E24*F24/1000 | H24: 15000 | I24: =IFERROR(E24*H24/1000,"") | J24: =I24
A25: Gia vị | J25: 800
D26: GAS | J26: 1250
D27: Chi phí khay,đũa | J27: 1600
A28: Tổng chi phí TĐ 1 | J28: =SUM(J20:J27)
A29: Cost TĐ 1 | J29: =J28/20000
A31: CHIẾT TÍNH THỰC ĐƠN CA Trưa 40.000đ
A32: Cơ cấu | B32: Món ăn | C32: Mã hàng | D32: Nguyên liệu | E32: Định lượng sống | F32: Số suất | G32: Gọi hàng | H32: Đơn giá | I32: Thành tiền | J32: Tổng
B33: bò kho dưa | C33: NLT0435 | D33: Thịt dẻ sườn trâu 123 | E33: 70 | F33: 2050 | G33: =E33*F33/1000 | H33: 120000 | I33: =IFERROR(E33*H33/1000,"") | J33: =I33
C34: NLR0025 | D34: cải bẹ | E34: 50 | F34: 2050 | G34: =E34*F34/1000 | H34: 9000 | I34: =IFERROR(E34*H34/1000,"") | J34: =I34
C35: NLR0268 | D35: cà chua to | E35: 3 | F35: 2050 | G35: =E35*F35/1000 | H35: 22000 | I35: =IFERROR(E35*H35/1000,"") | J35: =I35
B36: ức gà chiên xù | C36: NLT0107 | D36: Ức gà không xương | E36: 65 | F36: 2050 | G36: =E36*F36/1000 | H36: 57000 | I36: =IFERROR(E36*H36/1000,"") | J36: =I36
B37: lạc chao | C37: NLT0020 | D37: lạc nhân | E37: 40 | F37: 2050 | G37: =E37*F37/1000 | H37: 50000 | I37: =IFERROR(E37*H37/1000,"") | J37: =I37
B38: su su cà rốt luộc | C38: NLR0165 | D38: su su | E38: 110 | F38: 2050 | G38: =E38*F38/1000 | H38: 9000 | I38: =IFERROR(E38*H38/1000,"") | J38: =I38
C39: NLR0018 | D39: cà rốt | E39: 10 | F39: 2050 | G39: =E39*F39/1000 | H39: 11000 | I39: =IFERROR(E39*H39/1000,"") | J39: =I39
B40: cơm trắng | C40: NLG0013 | D40: gạo bắc hương | E40: 180 | F40: 2050 | G40: =E40*F40/1000 | H40: 13800 | I40: =IFERROR(E40*H40/1000,"") | J40: =I40
B41: canh cải ngọt | C41: NLR0032 | D41: cải ngọt cắt gốc | E41: 15 | F41: 2050 | G41: =E41*F41/1000 | H41: 11000 | I41: =IFERROR(E41*H41/1000,"") | J41: =I41
B42: dưa hấu | C42: NLQ0013 | D42: Dưa hấu 1,8- 3kg/quả | E42: 110 | F42: 2050 | G42: =E42*F42/1000 | H42: 10000 | I42: =IFERROR(E42*H42/1000,"") | J42: =I42
A43: Gia vị | J43: 1600
D44: Gas | J44: 1250
...

Sheet Chủ nhật
A2: Bữa Sáng 20.000Đ | G2: a
A3: Cơ cấu | B3: Món ăn | C3: Mã hàng | D3: Nguyên liệu | E3: Định lượng sống | F3: Số suất | G3: Gọi hàng | H3: Đơn giá | I3: Thành tiền | J3: Tổng
B4: bánh chưng + sữa fami | C4: NLG0011 | D4: bánh chưng | E4: 1000 | F4: 2000 | G4: =E4*F4/1000 | H4: 10000 | I4: =IFERROR(E4*H4/1000,"") | J4: =I4
C5: HHS0051 | D5: sữa fami bịch | E5: 1000 | F5: 2000 | G5: =E5*F5/1000 | H5: 3400 | I5: =IFERROR(E5*H5/1000,"") | J5: =I5
A6: Gia vị | J6: 0
D7: GAS | J7: 0
D8: Chi phí khay,đũa | J8: 1000
A9: Tổng chi phí TĐ 1 | J9: =SUM(J4:J8)
A10: Cost TĐ 1 | J10: =J9/20000
A12: CHIẾT TÍNH THỰC ĐƠN CA Trưa 40.000đ
A13: Cơ cấu | B13: Món ăn | C13: Mã hàng | D13: Nguyên liệu | E13: Định lượng sống | F13: Số suất | G13: Gọi hàng | H13: Đơn giá | I13: Thành tiền | J13: Tổng
B14: tôm rim me | C14: NLS0081 | D14: Tôm dảo tươi 100-120 | E14: 50 | F14: 1800 | G14: =E14*F14/1000 | H14: 147000 | I14: =IFERROR(E14*H14/1000,"") | J14: =I14
C15: NPG0094 | D15: me khô | E15: 1 | F15: 1800 | G15: =E15*F15/1000 | H15: 30000 | I15: =IFERROR(E15*H15/1000,"") | J15: =I15
B16: thịt xào hành tây | D16: thịt lợn mông sấn | E16: 70 | F16: 1800 | G16: =E16*F16/1000 | H16: 60000 | I16: =IFERROR(E16*H16/1000,"") | J16: =I16
C17: NLR0083 | D17: hành tây | E17: 40 | F17: 1800 | G17: =E17*F17/1000 | H17: 9000 | I17: =IFERROR(E17*H17/1000,"") | J17: =I17
C18: NLR0018 | D18: cà rốt | E18: 10 | F18: 1800 | G18: =E18*F18/1000 | H18: 11000 | I18: =IFERROR(E18*H18/1000,"") | J18: =I18
C19: NLR0042 | D19: cần tây | E19: 1 | F19: 1800 | G19: =E19*F19/1000 | H19: 35000 | I19: =IFERROR(E19*H19/1000,"") | J19: =I19
B20: ốc om chuối | D20: ruột ốc bươu | E20: 30 | F20: 1800 | G20: =E20*F20/1000 | H20: 55000 | I20: =IFERROR(E20*H20/1000,"") | J20: =I20
C21: NLR0051 | D21: chuối xanh | E21: 70 | F21: 1800 | G21: =E21*F21/1000 | H21: 8000 | I21: =IFERROR(E21*H21/1000,"") | J21: =I21
C22: NLR0170 | D22: tía tô | E22: 1 | F22: 1800 | G22: =E22*F22/1000 | H22: 25000 | I22: =IFERROR(E22*H22/1000,"") | J22: =I22
B23: đỗ cove luộc | C23: NLR0068 | D23: đậu cô ve | E23: 100 | F23: 1800 | G23: =E23*F23/1000 | H23: 18000 | I23: =IFERROR(E23*H23/1000,"") | J23: =I23
B24: cơm trắng | C24: NLG0013 | D24: gạo bắc hương | E24: 180 | F24: 1800 | G24: =E24*F24/1000 | H24: 13800 | I24: =IFERROR(E24*H24/1000,"") | J24: =I24
B25: canh bí xanh | C25: NLR0266 | D25: bí xanh dài | E25: 15 | F25: 1800 | G25: =E25*F25/1000 | H25: 9000 | I25: =IFERROR(E25*H25/1000,"") | J25: =I25
B26: thạch | C26: HHB0027 | D26: Thạch Long Hải 95g* 100 cốc/thùng | E26: 1000 | F26: 1800 | G26: =E26*F26/1000 | H26: 1650 | I26: =IFERROR(E26*H26/1000,"") | J26: =I26
A27: Gia vị | J27: 1600
D28: Gas | J28: 2500
D29: Chi phí đũa thìa + điện nước | J29: 2800
A30: Tổng chi phí TĐ 1 | J30: =SUM(J14:J29)
A31: Cost TĐ 1 | J31: =J30/40000
A33: THỰC ĐƠN CA Chiều 40.000Đ
A34: Cơ cấu | B34: Món ăn | C34: Mã hàng | D34: Nguyên liệu | E34: Định lượng sống | F34: Số suất | G34: Gọi hàng | H34: Đơn giá | I34: Thành tiền | J34: Tổng
B35: cá chiên giềng | C35: NLS0491 | D35: Cá chim sơ chế bỏ đầu 0,8-1,5kg/con | E35: 135 | F35: 1650 | G35: =E35*F35/1000 | H35: 47000 | I35: =IFERROR(E35*H35/1000,"") | J35: =I35
C36: NLR0077 | D36: giềng xay | E36: 5 | F36: 1650 | G36: =E36*F36/1000 | H36: 15000 | I36: =IFERROR(E36*H36/1000,"") | J36: =I36
B37: ức gà xào sả ớt | C37: NLT0107 | D37: Ức gà không xương | E37: 70 | F37: 1650 | G37: =E37*F37/1000 | H37: 57000 | I37: =IFERROR(E37*H37/1000,"") | J37: =I37
D38: ớt chuông xanh | E38: 10 | F38: 1650 | G38: =E38*F38/1000 | H38: 35000 | I38: =IFERROR(E38*H38/1000,"") | J38: =I38
C39: NLR0311 | D39: ớt chuông đỏ | E39: 10 | F39: 1650 | G39: =E39*F39/1000 | H39: 35000 | I39: =IFERROR(E39*H39/1000,"") | J39: =I39
C40: NLR0083 | D40: hành tây | E40: 15 | F40: 1650 | G40: =E40*F40/1000 | H40: 9000 | I40: =IFERROR(E40*H40/1000,"") | J40: =I40
C41: NLR0175 | D41: sả củ | E41: 3 | F41: 1650 | G41: =E41*F41/1000 | H41: 15000 | I41: =IFERROR(E41*H41/1000,"") | J41: =I41
B42: lạc chao | C42: NLT0020 | D42: lạc nhân | E42: 40 | F42: 1650 | G42: =E42*F42/1000 | H42: 50000 | I42: =IFERROR(E42*H42/1000,"") | J42: =I42
B43: khoai tây xào | C43: NLR0100 | D43: khoai tây | E43: 100 | F43: 1650 | G43: =E43*F43/1000 | H43: 13000 | I43: =IFERROR(E43*H43/1000,"") | J43: =I43
...

Sheet Báo giá
F3: Cập nhật giấy báo giá
H4: giá nhập
A5: Mã hàng | B5: Tên mặt hàng | C5: Mã ncc | D5: Tên nhà cung cấp | E5: Mã bộ phận | F5: Tên bộ phận | G5: Đvt | H5: Đơn giá | I5: Ngày bắt đầu hl | J5: Ngày kết thúc hl | K5: Ngầm định | L5: Mã hàng
A6: HHB0027 | B6: Thạch Long Hải 95g* 100 cốc/thùng | D6: Thái dương | G6: Cốc | H6: 1650 | M6: HHB0027
A7: NLG0256 | B7: Miến dong Thanh Lộc 0.4kg/ túi | D7: Thái dương | G7: Túi | H7: 65000 | M7: NLG0256
A8: NLG0267 | B8: Hạt nêm Orchid 10kg/túi | D8: Thái dương | G8: kg | H8: 26000 | M8: NLG0267
A9: NLG0314 | B9: Gạo An Phát | D9: Thái dương | G9: kg | H9: 14000 | M9: NLG0314
A10: NLQ0006 | B10: Quả cam | D10: Thái dương | G10: kg | H10: 18000 | M10: NLQ0006
A11: HHB0173 | B11: Bánh chuối Hải Hà 30g/cái | C11: NNCC00276 | D11: Phù sa | G11: kg | H11: 7088.89 | I11: 45870 | J11: 45900 | K11: 1 | L11: HHB0173 | M11: HHB0173
A12: NLQ0016 | B12: Quả ổi 3-5 quả/kg | D12: Thái dương | G12: kg | H12: 10000 | M12: NLQ0016
A13: NLR0001 | B13: Bắp cải trắng | D13: Thái dương | G13: kg | H13: 9000 | M13: NLR0001
A14: NLR0008 | B14: Bí đỏ dài | D14: Thái dương | G14: kg | H14: 8000 | M14: NLR0008
A15: NLR0009 | B15: Bí ngô non | D15: Thái dương | G15: kg | H15: 8000 | M15: NLR0009
A16: NLR0018 | B16: Cà rốt | D16: Thái dương | G16: kg | H16: 11000 | M16: NLR0018
A17: NLR0024 | B17: Cà tím dài | D17: Thái dương | G17: kg | H17: 8000 | M17: NLR0024
A18: NLR0025 | B18: Cải bẹ | D18: Thái dương | G18: kg | H18: 9000 | M18: NLR0025
A19: NLR0026 | B19: Cải canh (kg) | D19: Thái dương | G19: kg | H19: 14000 | M19: NLR0026
A20: NLR0329 | B20: Cải chíp VN | D20: Thái dương | G20: kg | H20: 12000 | M20: NLR0329
A21: NLR0029 | B21: Cải chíp | D21: Thái dương | G21: kg | H21: 12000 | M21: NLR0029
A22: NLR0032 | B22: Cải ngọt cắt gốc | D22: Thái dương | G22: kg | H22: 11000 | M22: NLR0032
A23: NLR0034 | B23: Cải thảo | D23: Thái dương | G23: kg | H23: 8000 | M23: NLR0034
... A44: NLR0127 | B44: Nghệ củ | D44: Thái dương | G44: kg | H44: 20000 | M44: NLR0127
A45: NLR0137 | B45: Ớt cay | D45: Thái dương | F45: =279/48 | G45: kg | H45: 20000 | M45: NLR0137
A46: NLR0153 | B46: Rau mùi ta | D46: Thái dương | G46: kg | H46: 15000 | M46: NLR0153
A47: NLR0154 | B47: Rau mùi tàu | D47: Thái dương | G47: kg | H47: 25000 | M47: NLR0154
A48: NLR0159 | B48: Rau ngổ | D48: Thái dương | G48: kg | H48: 20000 | M48: NLR0159
A49: NLR0160 | B49: Rau răm | D49: Thái dương | G49: kg | H49: 20000 | M49: NLR0160
A50: NLR0165 | B50: Su su | D50: Thái dương | G50: kg | H50: 9000 | M50: NLR0165
A51: NLR0170 | B51: Tía tô | D51: Thái dương | G51: kg | H51: 25000 | M51: NLR0170
A52: NLR0172 | B52: Tỏi khô | D52: Thái dương | G52: kg | H52: 30000 | M52: NLR0172
A53: NLR0174 | B53: Thì là | D53: Thái dương | G53: kg | H53: 20000 | M53: NLR0174
A54: NLR0175 | B54: Sả củ | D54: Thái dương | G54: kg | H54: 15000 | M54: NLR0175
A55: NLR0177 | B55: Nấm đùi gà | D55: Thái dương | G55: kg | H55: 42000 | M55: NLR0177
A56: NLR0225 | B56: Rau vặt | D56: Thái dương | G56: kg | H56: 30000 | M56: NLR0225
A57: NLR0227 | B57: ớt sừng đỏ | D57: Thái dương | G57: kg | H57: 35000 | M57: NLR0227
... A148: NLT0144 | B148: Thịt mông trâu ĐL ấn Độ (M45) 20kg/thùng | D148: Thái dương | G148: kg | H148: 160000 | M148: NLT0144
A149: NLT0252 | B149: Thịt nạc vai ĐL Brazin ( 17-28)kg/thùng | D149: Thái dương | F149: F | G149: kg | H149: 94000 | M149: NLT0252
A150: NLT0294 | B150: Gà góc 1/4 SIMON Mỹ 15 kg/ thùng | D150: Thái dương | G150: kg | H150: 55000 | M150: NLT0294
A151: NLT0435 | B151: Thịt dẻ sườn trâu 123 | D151: Thái dương | G151: kg | H151: 120000 | M151: NLT0435
A152: NLT0499 | B152: Thịt ba chỉ ĐL Miratog Nga có da không xương 25-35kg/thùng | D152: Thái dương | G152: kg | H152: 103000 | M152: NLT0499
...

Sheet ORDER
A2: 0 | D2: ĐƠN GỌI HÀNG | F2: ĐƠN GỌI HÀNG
A4: STT | B4: MÃ HÀNG | C4: TÊN HÀNG | D4: SỐ LƯỢNG | F4: SỐ LƯỢNG | H4: ĐVT | J4: NCC | K4: THỜI GIAN GIAO | L4: ghi chú
A5: 21 | B5: =VLOOKUP(C5,'Báo giá'!B:L,11,0) | C5: {=_xlfn.UNIQUE(TRIM(N:N))} | E5: =SUMIF('Thứ 2'!D4:D43,ORDER!C5,'Thứ 2'!G4:G43) | H5: cái | J5: =VLOOKUP(C5,'Báo giá'!B:H,3,0)
B6: =VLOOKUP(C6,'Báo giá'!B:L,11,0) | C6: Bánh nếp | D6: =SUMIF('Thứ 6'!D:D,ORDER!C6,'Thứ 6'!G:G) | E6: =SUMIF('Thứ 4'!E:E,ORDER!D6,'Thứ 4'!H:H) | F6: 3030 | G6: =SUMIF('Chủ nhật'!D:D,ORDER!C6,'Chủ nhật'!G:G) | H6: cái | I6: =VLOOKUP(C6,[2]Sheet1!$F:$H,3,0) | J6: =+D6-I6 | K6: 3h | M6: =VLOOKUP(N6,[3]BG!D:I,6,0) | N6: Bánh nếp | O6: =SUMIF(C:C,N6,D:D)
B7: =VLOOKUP(C7,'Báo giá'!B:L,11,0) | C7: Trứng gà CN 1,9-2.1kg/khay | D7: =SUMIF('Thứ 6'!D:D,ORDER!C7,'Thứ 6'!G:G) | E7: =SUMIF('Thứ 2'!D35:D46,ORDER!C7,'Thứ 2'!G35:G46) | F7: 1200 | G7: 300 | H7: quả | I7: =VLOOKUP(C7,[2]Sheet1!$F:$H,3,0) | J7: =+D7-I7 | K7: 3h30 | M7: =VLOOKUP(N7,[3]BG!D:I,6,0) | N7: Trứng gà CN 1,9-2.1kg/khay | O7: =SUMIF(C:C,N7,D:D)
B8: =VLOOKUP(C8,'Báo giá'!B:L,11,0) | C8: Sữa TUS dâu | D8: =SUMIF('Thứ 6'!D:D,ORDER!C8,'Thứ 6'!G:G) | E8: =SUMIF('Thứ 2'!D37:D46,ORDER!C8,'Thứ 2'!G37:G46) | F8: 0 | G8: 0 | H8: =VLOOKUP(C8,'Báo giá'!B:H,6,0) | I8: =VLOOKUP(C8,[2]Sheet1!$F:$H,3,0) | J8: =+D8-I8 | K8: 3h30 | M8: =VLOOKUP(N8,[3]BG!D:I,6,0) | N8: Sữa TUS dâu | O8: =SUMIF(C:C,N8,D:D)
B9: =VLOOKUP(C9,'Báo giá'!B:L,11,0) | C9: Thịt Trâu ĐL Má Đào 20kg/thùng | D9: =SUMIF('Thứ 6'!D:D,ORDER!C9,'Thứ 6'!G:G) | E9: =SUMIF('Thứ 2'!D43:D46,ORDER!C9,'Thứ 2'!G43:G46) | F9: 30 | G9: 0 | H9: =VLOOKUP(C9,'Báo giá'!B:H,6,0) | I9: =VLOOKUP(C9,[2]Sheet1!$F:$H,3,0) | J9: =+D9-I9 | K9: 3h30 | M9: =VLOOKUP(N9,[3]BG!D:I,6,0) | N9: Thịt Trâu ĐL Má Đào 20kg/thùng | O9: =SUMIF(C:C,N9,D:D)
B10: =VLOOKUP(C10,'Báo giá'!B:L,11,0) | C10: khoai tây | D10: =SUMIF('Thứ 6'!D:D,ORDER!C10,'Thứ 6'!G:G) | E10: =SUMIF('Thứ 2'!D44:D51,ORDER!C10,'Thứ 2'!G44:G51) | F10: 40 | G10: =SUMIF('Chủ nhật'!D:D,ORDER!C10,'Chủ nhật'!G:G) | H10: kg | I10: =VLOOKUP(C10,[2]Sheet1!$F:$H,3,0) | J10: =+D10-I10 | K10: 3h30 | M10: =VLOOKUP(N10,[3]BG!D:I,6,0) | N10: khoai tây | O10: =SUMIF(C:C,N10,D:D)
B11: =VLOOKUP(C11,'Báo giá'!B:L,11,0) | C11: cà rốt | D11: =SUMIF('Thứ 6'!D:D,ORDER!C11,'Thứ 6'!G:G) | E11: =SUMIF('Thứ 2'!D46:D51,ORDER!C11,'Thứ 2'!G46:G51) | F11: 32 | G11: =SUMIF('Chủ nhật'!D:D,ORDER!C11,'Chủ nhật'!G:G) | H11: =VLOOKUP(C11,'Báo giá'!B:H,6,0) | I11: =VLOOKUP(C11,[2]Sheet1!$F:$H,3,0) | J11: =+D11-I11 | K11: 3h30 | M11: =VLOOKUP(N11,[3]BG!D:I,6,0) | N11: cà rốt | O11: =SUMIF(C:C,N11,D:D)
B12: =VLOOKUP(C12,'Báo giá'!B:L,11,0) | C12: Miến dong Túi 0.5kg/ túi | D12: =SUMIF('Thứ 6'!D:D,ORDER!C12,'Thứ 6'!G:G) | E12: =SUMIF('Thứ 2'!D46:D55,ORDER!C12,'Thứ 2'!G46:G55) | F12: 160 | G12: 6 | H12: =VLOOKUP(C12,'Báo giá'!B:H,6,0) | I12: =VLOOKUP(C12,[2]Sheet1!$F:$H,3,0) | J12: =+D12-I12 | K12: 3h30 | M12: =VLOOKUP(N12,[3]BG!D:I,6,0) | N12: Trứng gà CN 1,9-2.1kg/khay | O12: =SUMIF(C:C,N12,D:D)
B13: =VLOOKUP(C13,'Báo giá'!B:L,11,0) | C13: Chả lụa đông lạnh Dabaco | D13: =SUMIF('Thứ 6'!D:D,ORDER!C13,'Thứ 6'!G:G) | E13: =SUMIF('Thứ 2'!D46:D55,ORDER!C13,'Thứ 2'!G46:G55) | F13: 40.8 | G13: =SUMIF('Chủ nhật'!D:D,ORDER!C13,'Chủ nhật'!G:G) | H13: =VLOOKUP(C13,'Báo giá'!B:H,6,0) | I13: =VLOOKUP(C13,[2]Sheet1!$F:$H,3,0) | J13: =+D13-I13 | K13: 3h30 | M13: =VLOOKUP(N13,[3]BG!D:I,6,0) | N13: Miến dong Túi 0.5kg/ túi | O13: =SUMIF(C:C,N13,D:D)
B14: =VLOOKUP(C14,'Báo giá'!B:L,11,0) | C14: bắp cải trắng | D14: =SUMIF('Thứ 6'!D:D,ORDER!C14,'Thứ 6'!G:G) | E14: =SUMIF('Thứ 2'!D47:D62,ORDER!C14,'Thứ 2'!G47:G62) | F14: 1 | G14: =SUMIF('Chủ nhật'!D:D,ORDER!C14,'Chủ nhật'!G:G) | H14: =VLOOKUP(C14,'Báo giá'!B:H,6,0) | I14: =VLOOKUP(C14,[2]Sheet1!$F:$H,3,0) | J14: =+D14-I14 | K14: 3h30 | M14: =VLOOKUP(N14,[3]BG!D:I,6,0) | N14: Chả lụa đông lạnh Dabaco | O14: =SUMIF(C:C,N14,D:D) | S14: =70*750
B15: =VLOOKUP(C15,'Báo giá'!B:L,11,0) | C15: Măng khô | D15: =SUMIF('Thứ 6'!D:D,ORDER!C15,'Thứ 6'!G:G) | E15: =SUMIF('Thứ 2'!D47:D63,ORDER!C15,'Thứ 2'!G47:G63) | F15: 0 | G15: 0.5 | H15: kg | I15: =VLOOKUP(C15,[2]Sheet1!$F:$H,3,0) | J15: =+D15-I15 | K15: 3h30 | M15: =VLOOKUP(N15,[3]BG!D:I,6,0) | N15: bắp cải trắng | O15: =SUMIF(C:C,N15,D:D)
B16: =VLOOKUP(C16,'Báo giá'!B:L,11,0) | C16: cải ngồng | D16: =SUMIF('Thứ 6'!D:D,ORDER!C16,'Thứ 6'!G:G) | E16: =SUMIF('Thứ 2'!D52:D64,ORDER!C16,'Thứ 2'!G52:G64) | F16: 0 | G16: 73 | H16: =VLOOKUP(C16,'Báo giá'!B:H,6,0) | I16: =VLOOKUP(C16,[2]Sheet1!$F:$H,3,0) | J16: =+D16-I16 | K16: 3h30 | M16: =VLOOKUP(N16,[3]BG!D:I,6,0) | N16: Măng khô | O16: =SUMIF(C:C,N16,D:D)
B17: =VLOOKUP(C17,'Báo giá'!B:L,11,0) | C17: gạo bắc hương | D17: =SUMIF('Thứ 6'!D:D,ORDER!C17,'Thứ 6'!G:G) | E17: =SUMIF('Thứ 2'!D55:D65,ORDER!C17,'Thứ 2'!G55:G65) | F17: 90 | G17: 0 | H17: =VLOOKUP(C17,'Báo giá'!B:H,6,0) | I17: =VLOOKUP(C17,[2]Sheet1!$F:$H,3,0) | J17: =+D17-I17 | K17: 3h30 | M17: =VLOOKUP(N17,[3]BG!D:I,6,0) | N17: cải ngồng | O17: =SUMIF(C:C,N17,D:D)
B18: =VLOOKUP(C18,'Báo giá'!B:L,11,0) | C18: rau mồng tơi | D18: =SUMIF('Thứ 6'!D:D,ORDER!C18,'Thứ 6'!G:G) | E18: =SUMIF('Thứ 2'!D55:D65,ORDER!C18,'Thứ 2'!G55:G65) | F18: 10 | G18: 8 | H18: =VLOOKUP(C18,'Báo giá'!B:H,6,0) | I18: =VLOOKUP(C18,[2]Sheet1!$F:$H,3,0) | J18: =+D18-I18 | K18: 3h30 | M18: =VLOOKUP(N18,[3]BG!D:I,6,0) | N18: gạo bắc hương | O18: =SUMIF(C:C,N18,D:D)
B19: =VLOOKUP(C19,'Báo giá'!B:L,11,0) | C19: Quả ổi 3-5 quả/kg | D19: =SUMIF('Thứ 6'!D:D,ORDER!C19,'Thứ 6'!G:G) | E19: =SUMIF('Thứ 2'!D61:D65,ORDER!C19,'Thứ 2'!G61:G65) | F19: 132 | G19: =SUMIF('Chủ nhật'!D:D,ORDER!C19,'Chủ nhật'!G:G) | H19: kg | I19: =VLOOKUP(C19,[2]Sheet1!$F:$H,3,0) | J19: =+D19-I19 | K19: 3h30 | M19: =VLOOKUP(N19,[3]BG!D:I,6,0) | N19: rau mồng tơi | O19: =SUMIF(C:C,N19,D:D)
B20: =VLOOKUP(C20,'Báo giá'!B:L,11,0) | C20: Thịt gà CN không đầu, cổ cánh >1.8kg/con | D20: =SUMIF('Thứ 6'!D:D,ORDER!C20,'Thứ 6'!G:G) | E20: =SUMIF('Thứ 2'!D63:D65,ORDER!C20,'Thứ 2'!G63:G65) | F20: 0 | G20: 70 | H20: =VLOOKUP(C20,'Báo giá'!B:H,6,0) | I20: =VLOOKUP(C20,[2]Sheet1!$F:$H,3,0) | J20: =+D20-I20 | K20: 3h30 | M20: =VLOOKUP(N20,[3]BG!D:I,6,0) | N20: Quả ổi 3-5 quả/kg | O20: =SUMIF(C:C,N20,D:D)
B21: =VLOOKUP(C21,'Báo giá'!B:L,11,0) | C21: lá chanh (kg) | D21: =SUMIF('Thứ 6'!D:D,ORDER!C21,'Thứ 6'!G:G) | E21: =SUMIF('Thứ 2'!D63:D66,ORDER!C21,'Thứ 2'!G63:G66) | F21: 16 | G21: 0.1 | H21: =VLOOKUP(C21,'Báo giá'!B:H,6,0) | I21: =VLOOKUP(C21,[2]Sheet1!$F:$H,3,0) | J21: =+D21-I21 | K21: 3h30 | M21: =VLOOKUP(N21,[3]BG!D:I,6,0) | N21: Thịt gà CN không đầu, cổ cánh >1.8kg/con | O21: =SUMIF(C:C,N21,D:D)
B22: =VLOOKUP(C22,'Báo giá'!B:L,11,0) | C22: Ức gà không xương không ra | D22: =SUMIF('Thứ 6'!D:D,ORDER!C22,'Thứ 6'!G:G) | E22: =SUMIF('Thứ 2'!D63:D69,ORDER!C22,'Thứ 2'!G63:G69) | F22: 1020 | G22: 17 | H22: =VLOOKUP(C22,'Báo giá'!B:H,6,0) | I22: =VLOOKUP(C22,[2]Sheet1!$F:$H,3,0) | J22: =+D22-I22 | K22: 3h30 | M22: =VLOOKUP(N22,[3]BG!D:I,6,0) | N22: lá chanh (kg) | O22: =SUMIF(C:C,N22,D:D)
B23: =VLOOKUP(C23,'Báo giá'!B:L,11,0) | C23: Mỡ khổ | D23: =SUMIF('Thứ 6'!D:D,ORDER!C23,'Thứ 6'!G:G) | E23: =SUMIF('Thứ 2'!D65:D70,ORDER!C23,'Thứ 2'!G65:G70) | F23: 70 | G23: 3.7 | H23: kg | I23: =VLOOKUP(C23,[2]Sheet1!$F:$H,3,0) | J23: =+D23-I23 | K23: 3h30 | M23: =VLOOKUP(N23,[3]BG!D:I,6,0) | N23: Chả lụa đông lạnh Dabaco | O23: =SUMIF(C:C,N23,D:D)
B24: =VLOOKUP(C24,'Báo giá'!B:L,11,0) | C24: Lá lốt không cành kg | D24: =SUMIF('Thứ 6'!D:D,ORDER!C24,'Thứ 6'!G:G) | E24: =SUMIF('Thứ 2'!D65:D71,ORDER!C24,'Thứ 2'!G65:G71) | F24: 50 | G24: 6 | H24: kg | I24: =VLOOKUP(C24,[2]Sheet1!$F:$H,3,0) | J24: =+D24-I24 | K24: 3h30 | M24: =VLOOKUP(N24,[3]BG!D:I,6,0) | N24: Ức gà không xương không ra | O24: =SUMIF(C:C,N24,D:D)
B25: =VLOOKUP(C25,'Báo giá'!B:L,11,0) | C25: su su | D25: =SUMIF('Thứ 6'!D:D,ORDER!C25,'Thứ 6'!G:G) | E25: =SUMIF('Thứ 2'!D66:D72,ORDER!C25,'Thứ 2'!G66:G72) | F25: 80 | G25: 60 | H25: kg | I25: =VLOOKUP(C25,[2]Sheet1!$F:$H,3,0) | J25: =+D25-I25 | K25: 3h30 | M25: =VLOOKUP(N25,[3]BG!D:I,6,0) | N25: Mỡ khổ | O25: =SUMIF(C:C,N25,D:D)
B26: =VLOOKUP(C26,'Báo giá'!B:L,11,0) | C26: Cải xanh cắt gốc (kg) | D26: =SUMIF('Thứ 6'!D:D,ORDER!C26,'Thứ 6'!G:G) | E26: =SUMIF('Thứ 2'!D66:D77,ORDER!C26,'Thứ 2'!G66:G77) | F26: 15 | G26: =SUMIF('Chủ nhật'!D:D,ORDER!C26,'Chủ nhật'!G:G) | H26: kg | I26: =VLOOKUP(C26,[2]Sheet1!$F:$H,3,0) | J26: =+D26-I26 | K26: 3h30 | M26: =VLOOKUP(N26,[3]BG!D:I,6,0) | N26: Lá lốt không cành kg | O26: =SUMIF(C:C,N26,D:D)
B27: =VLOOKUP(C27,'Báo giá'!B:L,11,0) | C27: gừng củ | D27: =SUMIF('Thứ 6'!D:D,ORDER!C27,'Thứ 6'!G:G) | E27: =SUMIF('Thứ 2'!D66:D77,ORDER!C27,'Thứ 2'!G66:G77) | F27: 90 | G27: 0 | H27: kg | I27: =VLOOKUP(C27,[2]Sheet1!$F:$H,3,0) | J27: =+D27-I27 | K27: 3h30 | M27: =VLOOKUP(N27,[3]BG!D:I,6,0) | N27: cà rốt | O27: =SUMIF(C:C,N27,D:D)
B28: =VLOOKUP(C28,'Báo giá'!B:L,11,0) | C28: Cam sành 4-6 quả/kg | D28: =SUMIF('Thứ 6'!D:D,ORDER!C28,'Thứ 6'!G:G) | E28: =SUMIF('Thứ 2'!D66:D77,ORDER!C28,'Thứ 2'!G66:G77) | F28: 1 | G28: =SUMIF('Chủ nhật'!D:D,ORDER!C28,'Chủ nhật'!G:G) | H28: kg | I28: =VLOOKUP(C28,[2]Sheet1!$F:$H,3,0) | J28: =+D28-I28 | K28: 5h | M28: =VLOOKUP(N28,[3]BG!D:I,6,0) | N28: su su
B29: =VLOOKUP(C29,'Báo giá'!B:L,11,0) | C29: 50 | D29: =SUMIF('Thứ 6'!D:D,ORDER!C29,'Thứ 6'!G:G) | E29: =SUMIF('Thứ 2'!D69:D77,ORDER!C29,'Thứ 2'!G69:G77) | F29: 1 | G29: 0 | H29: quả | I29: =VLOOKUP(C29,[2]Sheet1!$F:$H,3,0) | J29: =+D29-I29 | K29: 5h | M29: =VLOOKUP(N29,[3]BG!D:I,6,0) | N29: gạo bắc hương
B30: =VLOOKUP(C30,'Báo giá'!B:L,11,0) | C30: Trứng gà CN bóc vỏ 1,9-2.1kg/khay | D30: =SUMIF('Thứ 6'!D:D,ORDER!C30,'Thứ 6'!G:G) | E30: =SUMIF('Thứ 2'!D70:D77,ORDER!C30,'Thứ 2'!G70:G77) | F30: 0 | G30: 520 | H30: kg | I30: =VLOOKUP(C30,[2]Sheet1!$F:$H,3,0) | J30: =+D30-I30 | K30: 3h30 | N30: Cải xanh cắt gốc (kg)
D31: =SUMIF('Thứ 6'!D:D,ORDER!C31,'Thứ 6'!G:G) | F31: 5 | H31: kg | K31: 3h30 | N31: gừng củ
D32: =SUMIF('Thứ 6'!D:D,ORDER!C32,'Thứ 6'!G:G) | F32: 30 | H32: túi | K32: 3h30 | N32: Cam sành 4-6 quả/kg
D33: =SUMIF('Thứ 6'!D:D,ORDER!C33,'Thứ 6'!G:G) | F33: 1 | H33: kg | K33: 3h30
C34: Xúc xích ĐV Chicago 0.5kg/gói | D34: =SUMIF('Thứ 6'!D:D,ORDER!C34,'Thứ 6'!G:G) | F34: 0 | G34: 30 | H34: kg | K34: 3h30 | N34: 50
C35: Dầu ăn orchid 19.8 lít / thùng | D35: =SUMIF('Thứ 6'!D:D,ORDER!C35,'Thứ 6'!G:G) | F35: 2 | G35: 2 | H35: Thùng | K35: 3h30
C36: ớt cay | D36: =SUMIF('Thứ 6'!D:D,ORDER!C36,'Thứ 6'!G:G) | F36: 2.5 | G36: 1 | H36: kg | K36: 3h30
C37: Thịt nạc vai ĐL Brazin ( 17-28)kg/thùng | G37: 40 | H37: kg
